Workbook

Sheet Painel de Crédito
A1: DCM CREDIT SCREENING | ANÁLISE DE OPORTUNIDADES DE DÍVIDA | BASE: ÚLTIMO QUARTER LTM DIVULGADO
A2: IDENTIFICAÇÃO | D2: INDICADORES DE CRÉDITO E LIQUIDEZ | O2: TRIGGERS / CATALISADORES
A3: Empresa | B3: Ticker | C3: Setor | D3: Dívida Bruta (R$ mm) | E3: Caixa (R$ mm) | F3: Dívida Líquida (R$ mm) | G3: EBITDA LTM (R$ mm) | H3: Dív Líq / EBITDA (x) | I3: EBITDA / Desp Fin (x) | J3: Custo Médio Dívida % aa | K3: Duration Média (anos) | L3: % CP Dívida | M3: Dívida CP (R$ mm) | N3: Caixa / Dívida CP (x) | O3: Covenants Financeiros | P3: Guidance Capex 12-24m | Q3: M&A Recente | R3: Observações / Oportunidade
A4: ⚠ Convenção de cores de texto: Azul = Input manual (hardcode) | Preto = Fórmula | Verde = Link cross-sheet | Amarelo = Atenção / Atualizar
A5: Energisa | B5: ENGI11 | C5: Energia Elétrica | D5: ='Inputs — DFs'!Q6 -> 0 | E5: ='Inputs — DFs'!S6 -> 0 | F5: =IF(AND(D5<>"",E5<>""),D5-E5,"") -> 0 | G5: ='Inputs — DFs'!V6 -> 0 | H5: =IF(AND(G5<>"",((G5)<>0)),F5/G5,"") | I5: ='Inputs — DFs'!Y6 | L5: ='Inputs — DFs'!Z6 | M5: ='Inputs — DFs'!AA6 -> 0 | N5: =IF(AND(M5<>"",((M5)<>0)),E5/M5,"")
A6: Cemig | B6: CMIG4 | C6: Energia Elétrica | D6: ='Inputs — DFs'!Q7 -> 0 | E6: ='Inputs — DFs'!S7 -> 0 | F6: =IF(AND(D6<>"",E6<>""),D6-E6,"") -> 0 | G6: ='Inputs — DFs'!V7 -> 0 | H6: =IF(AND(G6<>"",((G6)<>0)),F6/G6,"") | I6: ='Inputs — DFs'!Y7 | L6: ='Inputs — DFs'!Z7 | M6: ='Inputs — DFs'!AA7 -> 0 | N6: =IF(AND(M6<>"",((M6)<>0)),E6/M6,"")
A7: CPFL | B7: CPFE3 | C7: Energia Elétrica | D7: ='Inputs — DFs'!Q8 -> 0 | E7: ='Inputs — DFs'!S8 -> 0 | F7: =IF(AND(D7<>"",E7<>""),D7-E7,"") -> 0 | G7: ='Inputs — DFs'!V8 -> 0 | H7: =IF(AND(G7<>"",((G7)<>0)),F7/G7,"") | I7: ='Inputs — DFs'!Y8 | L7: ='Inputs — DFs'!Z8 | M7: ='Inputs — DFs'!AA8 -> 0 | N7: =IF(AND(M7<>"",((M7)<>0)),E7/M7,"")
A8: Desktop | B8: DESK3 | C8: Telecom / ISP | D8: ='Inputs — DFs'!Q9 -> 0 | E8: ='Inputs — DFs'!S9 -> 0 | F8: =IF(AND(D8<>"",E8<>""),D8-E8,"") -> 0 | G8: ='Inputs — DFs'!V9 -> 0 | H8: =IF(AND(G8<>"",((G8)<>0)),F8/G8,"") | I8: ='Inputs — DFs'!Y9 | L8: ='Inputs — DFs'!Z9 | M8: ='Inputs — DFs'!AA9 -> 0 | N8: =IF(AND(M8<>"",((M8)<>0)),E8/M8,"")
A9: Unifique | B9: FIQE3 | C9: Telecom / ISP | D9: ='Inputs — DFs'!Q10 -> 0 | E9: ='Inputs — DFs'!S10 -> 0 | F9: =IF(AND(D9<>"",E9<>""),D9-E9,"") -> 0 | G9: ='Inputs — DFs'!V10 -> 0 | H9: =IF(AND(G9<>"",((G9)<>0)),F9/G9,"") | I9: ='Inputs — DFs'!Y10 | L9: ='Inputs — DFs'!Z10 | M9: ='Inputs — DFs'!AA10 -> 0 | N9: =IF(AND(M9<>"",((M9)<>0)),E9/M9,"")
A10: Brisanet | B10: BRIT3 | C10: Telecom / ISP | D10: ='Inputs — DFs'!Q11 -> 0 | E10: ='Inputs — DFs'!S11 -> 0 | F10: =IF(AND(D10<>"",E10<>""),D10-E10,"") -> 0 | G10: ='Inputs — DFs'!V11 -> 0 | H10: =IF(AND(G10<>"",((G10)<>0)),F10/G10,"") | I10: ='Inputs — DFs'!Y11 | L10: ='Inputs — DFs'!Z11 | M10: ='Inputs — DFs'!AA11 -> 0 | N10: =IF(AND(M10<>"",((M10)<>0)),E10/M10,"")
A11: Vero | B11: N/A | C11: Telecom / ISP | D11: ='Inputs — DFs'!Q12 -> 0 | E11: ='Inputs — DFs'!S12 -> 0 | F11: =IF(AND(D11<>"",E11<>""),D11-E11,"") -> 0 | G11: ='Inputs — DFs'!V12 -> 0 | H11: =IF(AND(G11<>"",((G11)<>0)),F11/G11,"") | I11: ='Inputs — DFs'!Y12 | L11: ='Inputs — DFs'!Z12 | M11: ='Inputs — DFs'!AA12 -> 0 | N11: =IF(AND(M11<>"",((M11)<>0)),E11/M11,"")
A12: Alloha | B12: N/A | C12: Telecom / ISP | D12: ='Inputs — DFs'!Q13 -> 0 | E12: ='Inputs — DFs'!S13 -> 0 | F12: =IF(AND(D12<>"",E12<>""),D12-E12,"") -> 0 | G12: ='Inputs — DFs'!V13 -> 0 | H12: =IF(AND(G12<>"",((G12)<>0)),F12/G12,"") | I12: ='Inputs — DFs'!Y13 | L12: ='Inputs — DFs'!Z13 | M12: ='Inputs — DFs'!AA13 -> 0 | N12: =IF(AND(M12<>"",((M12)<>0)),E12/M12,"")
A13: Alares | B13: N/A | C13: Telecom / ISP | D13: ='Inputs — DFs'!Q14 -> 0 | E13: ='Inputs — DFs'!S14 -> 0 | F13: =IF(AND(D13<>"",E13<>""),D13-E13,"") -> 0 | G13: ='Inputs — DFs'!V14 -> 0 | H13: =IF(AND(G13<>"",((G13)<>0)),F13/G13,"") | I13: ='Inputs — DFs'!Y14 | L13: ='Inputs — DFs'!Z14 | M13: ='Inputs — DFs'!AA14 -> 0 | N13: =IF(AND(M13<>"",((M13)<>0)),E13/M13,"")
A14: Tecpar / BrTecPar | B14: N/A | C14: Telecom / ISP | D14: ='Inputs — DFs'!Q15 -> 0 | E14: ='Inputs — DFs'!S15 -> 0 | F14: =IF(AND(D14<>"",E14<>""),D14-E14,"") -> 0 | G14: ='Inputs — DFs'!V15 -> 0 | H14: =IF(AND(G14<>"",((G14)<>0)),F14/G14,"") | I14: ='Inputs — DFs'!Y15 | L14: ='Inputs — DFs'!Z15 | M14: ='Inputs — DFs'!AA15 -> 0 | N14: =IF(AND(M14<>"",((M14)<>0)),E14/M14,"")
A15: Algar | B15: ALGT3 | C15: Telecom / ISP | D15: ='Inputs — DFs'!Q16 -> 0 | E15: ='Inputs — DFs'!S16 -> 0 | F15: =IF(AND(D15<>"",E15<>""),D15-E15,"") -> 0 | G15: ='Inputs — DFs'!V16 -> 0 | H15: =IF(AND(G15<>"",((G15)<>0)),F15/G15,"") | I15: ='Inputs — DFs'!Y16 | L15: ='Inputs — DFs'!Z16 | M15: ='Inputs — DFs'!AA16 -> 0 | N15: =IF(AND(M15<>"",((M15)<>0)),E15/M15,"")
A16: TIM | B16: TIMS3 | C16: Telecom | D16: ='Inputs — DFs'!Q17 -> 0 | E16: ='Inputs — DFs'!S17 -> 0 | F16: =IF(AND(D16<>"",E16<>""),D16-E16,"") -> 0 | G16: ='Inputs — DFs'!V17 -> 0 | H16: =IF(AND(G16<>"",((G16)<>0)),F16/G16,"") | I16: ='Inputs — DFs'!Y17 | L16: ='Inputs — DFs'!Z17 | M16: ='Inputs — DFs'!AA17 -> 0 | N16: =IF(AND(M16<>"",((M16)<>0)),E16/M16,"")
... A50: Smartfit | B50: SMFT3 | C50: Fitness / Saúde | D50: ='Inputs — DFs'!Q51 -> 0 | E50: ='Inputs — DFs'!S51 -> 0 | F50: =IF(AND(D50<>"",E50<>""),D50-E50,"") -> 0 | G50: ='Inputs — DFs'!V51 -> 0 | H50: =IF(AND(G50<>"",((G50)<>0)),F50/G50,"") | I50: ='Inputs — DFs'!Y51 | L50: ='Inputs — DFs'!Z51 | M50: ='Inputs — DFs'!AA51 -> 0 | N50: =IF(AND(M50<>"",((M50)<>0)),E50/M50,"")
A51: TOTAL (46 empresas) | D51: =SUM(D5:D50) -> 0 | E51: =SUM(E5:E50) -> 0 | F51: =SUM(F5:F50) -> 0 | G51: =SUM(G5:G50) -> 0 | M51: =SUM(M5:M50) -> 0

Sheet Inputs — DFs
A1: INPUTS — DEMONSTRAÇÕES FINANCEIRAS | EXTRAÇÃO DIRETA DAS NOTAS EXPLICATIVAS (DFP / ITR)
A2: Azul = input manual (hardcode extraído da DF) | Preto = fórmula automática | Verde = valor exportado para 'Painel de Crédito' | Cinza = calculado nesta aba
A3: IDENTIFICAÇÃO | C3: BALANÇO — DÍVIDA (R$ mm) | I3: BALANÇO — CAIXA (R$ mm) | K3: P&L LTM (R$ mm) | Q3: DÍVIDA BRUTA CALC. | S3: CAIXA / DÍV. LÍQUIDA | V3: EBITDA | W3: DL/EBITDA | Y3: ICJ | Z3: LIQUIDEZ CP
A4: ℹ IFRS 16 (arrendamentos): preencher cols E e F se quiser comparar alavancagem com e sem leasing. Cols Q e W excluem IFRS16; cols R e X incluem. Deixar em branco se não aplicável.
A5: Empresa | B5: Período (ex: 4T24 LTM) | C5: Emp. & Fin. CP | D5: Emp. & Fin. LP | E5: Arrendam. CP (IFRS16) | F5: Arrendam. LP (IFRS16) | G5: Outros Passivos Fin. CP | H5: Outros Passivos Fin. LP | I5: Caixa e Equivalentes | J5: Aplicações Financ. CP | K5: Receita Líquida LTM | L5: EBIT LTM | M5: D&A LTM | N5: Desp. Financ. Bruta | O5: Rec. Financ. LTM | P5: Capex LTM | Q5: Dív. Bruta (sem IFRS16) | R5: Dív. Bruta (com IFRS16) | S5: Caixa Total | T5: Dív. Líq. (sem IFRS16) | U5: Dív. Líq. (com IFRS16) | V5: EBITDA LTM | W5: DL/EBITDA (sem IFRS16) | X5: DL/EBITDA (com IFRS16) | Y5: EBITDA / Desp Fin | Z5: % CP (sem IFRS16) | AA5: Dív. CP (sem IFRS16) | AB5: Caixa / Dív. CP
A6: Energisa | Q6: =IFERROR(C6+D6+G6+H6,"") -> 0 | R6: =IFERROR(C6+D6+E6+F6+G6+H6,"") -> 0 | S6: =IFERROR(I6+J6,"") -> 0 | T6: =IFERROR(Q6-S6,"") -> 0 | U6: =IFERROR(R6-S6,"") -> 0 | V6: =IFERROR(L6+M6,"") -> 0 | W6: =IFERROR(IF(V6=0,"",T6/V6),"") | X6: =IFERROR(IF(V6=0,"",U6/V6),"") | Y6: =IFERROR(IF(N6=0,"",V6/N6),"") | Z6: =IFERROR(IF(Q6=0,"",(C6+G6)/Q6),"") | AA6: =IFERROR(C6+G6,"") -> 0 | AB6: =IFERROR(IF(AA6=0,"",S6/AA6),"")
A7: Cemig | Q7: =IFERROR(C7+D7+G7+H7,"") -> 0 | R7: =IFERROR(C7+D7+E7+F7+G7+H7,"") -> 0 | S7: =IFERROR(I7+J7,"") -> 0 | T7: =IFERROR(Q7-S7,"") -> 0 | U7: =IFERROR(R7-S7,"") -> 0 | V7: =IFERROR(L7+M7,"") -> 0 | W7: =IFERROR(IF(V7=0,"",T7/V7),"") | X7: =IFERROR(IF(V7=0,"",U7/V7),"") | Y7: =IFERROR(IF(N7=0,"",V7/N7),"") | Z7: =IFERROR(IF(Q7=0,"",(C7+G7)/Q7),"") | AA7: =IFERROR(C7+G7,"") -> 0 | AB7: =IFERROR(IF(AA7=0,"",S7/AA7),"")
A8: CPFL | Q8: =IFERROR(C8+D8+G8+H8,"") -> 0 | R8: =IFERROR(C8+D8+E8+F8+G8+H8,"") -> 0 | S8: =IFERROR(I8+J8,"") -> 0 | T8: =IFERROR(Q8-S8,"") -> 0 | U8: =IFERROR(R8-S8,"") -> 0 | V8: =IFERROR(L8+M8,"") -> 0 | W8: =IFERROR(IF(V8=0,"",T8/V8),"") | X8: =IFERROR(IF(V8=0,"",U8/V8),"") | Y8: =IFERROR(IF(N8=0,"",V8/N8),"") | Z8: =IFERROR(IF(Q8=0,"",(C8+G8)/Q8),"") | AA8: =IFERROR(C8+G8,"") -> 0 | AB8: =IFERROR(IF(AA8=0,"",S8/AA8),"")
A9: Desktop | Q9: =IFERROR(C9+D9+G9+H9,"") -> 0 | R9: =IFERROR(C9+D9+E9+F9+G9+H9,"") -> 0 | S9: =IFERROR(I9+J9,"") -> 0 | T9: =IFERROR(Q9-S9,"") -> 0 | U9: =IFERROR(R9-S9,"") -> 0 | V9: =IFERROR(L9+M9,"") -> 0 | W9: =IFERROR(IF(V9=0,"",T9/V9),"") | X9: =IFERROR(IF(V9=0,"",U9/V9),"") | Y9: =IFERROR(IF(N9=0,"",V9/N9),"") | Z9: =IFERROR(IF(Q9=0,"",(C9+G9)/Q9),"") | AA9: =IFERROR(C9+G9,"") -> 0 | AB9: =IFERROR(IF(AA9=0,"",S9/AA9),"")
A10: Unifique | Q10: =IFERROR(C10+D10+G10+H10,"") -> 0 | R10: =IFERROR(C10+D10+E10+F10+G10+H10,"") -> 0 | S10: =IFERROR(I10+J10,"") -> 0 | T10: =IFERROR(Q10-S10,"") -> 0 | U10: =IFERROR(R10-S10,"") -> 0 | V10: =IFERROR(L10+M10,"") -> 0 | W10: =IFERROR(IF(V10=0,"",T10/V10),"") | X10: =IFERROR(IF(V10=0,"",U10/V10),"") | Y10: =IFERROR(IF(N10=0,"",V10/N10),"") | Z10: =IFERROR(IF(Q10=0,"",(C10+G10)/Q10),"") | AA10: =IFERROR(C10+G10,"") -> 0 | AB10: =IFERROR(IF(AA10=0,"",S10/AA10),"")
A11: Brisanet | Q11: =IFERROR(C11+D11+G11+H11,"") -> 0 | R11: =IFERROR(C11+D11+E11+F11+G11+H11,"") -> 0 | S11: =IFERROR(I11+J11,"") -> 0 | T11: =IFERROR(Q11-S11,"") -> 0 | U11: =IFERROR(R11-S11,"") -> 0 | V11: =IFERROR(L11+M11,"") -> 0 | W11: =IFERROR(IF(V11=0,"",T11/V11),"") | X11: =IFERROR(IF(V11=0,"",U11/V11),"") | Y11: =IFERROR(IF(N11=0,"",V11/N11),"") | Z11: =IFERROR(IF(Q11=0,"",(C11+G11)/Q11),"") | AA11: =IFERROR(C11+G11,"") -> 0 | AB11: =IFERROR(IF(AA11=0,"",S11/AA11),"")
A12: Vero | Q12: =IFERROR(C12+D12+G12+H12,"") -> 0 | R12: =IFERROR(C12+D12+E12+F12+G12+H12,"") -> 0 | S12: =IFERROR(I12+J12,"") -> 0 | T12: =IFERROR(Q12-S12,"") -> 0 | U12: =IFERROR(R12-S12,"") -> 0 | V12: =IFERROR(L12+M12,"") -> 0 | W12: =IFERROR(IF(V12=0,"",T12/V12),"") | X12: =IFERROR(IF(V12=0,"",U12/V12),"") | Y12: =IFERROR(IF(N12=0,"",V12/N12),"") | Z12: =IFERROR(IF(Q12=0,"",(C12+G12)/Q12),"") | AA12: =IFERROR(C12+G12,"") -> 0 | AB12: =IFERROR(IF(AA12=0,"",S12/AA12),"")
A13: Alloha | Q13: =IFERROR(C13+D13+G13+H13,"") -> 0 | R13: =IFERROR(C13+D13+E13+F13+G13+H13,"") -> 0 | S13: =IFERROR(I13+J13,"") -> 0 | T13: =IFERROR(Q13-S13,"") -> 0 | U13: =IFERROR(R13-S13,"") -> 0 | V13: =IFERROR(L13+M13,"") -> 0 | W13: =IFERROR(IF(V13=0,"",T13/V13),"") | X13: =IFERROR(IF(V13=0,"",U13/V13),"") | Y13: =IFERROR(IF(N13=0,"",V13/N13),"") | Z13: =IFERROR(IF(Q13=0,"",(C13+G13)/Q13),"") | AA13: =IFERROR(C13+G13,"") -> 0 | AB13: =IFERROR(IF(AA13=0,"",S13/AA13),"")
A14: Alares | Q14: =IFERROR(C14+D14+G14+H14,"") -> 0 | R14: =IFERROR(C14+D14+E14+F14+G14+H14,"") -> 0 | S14: =IFERROR(I14+J14,"") -> 0 | T14: =IFERROR(Q14-S14,"") -> 0 | U14: =IFERROR(R14-S14,"") -> 0 | V14: =IFERROR(L14+M14,"") -> 0 | W14: =IFERROR(IF(V14=0,"",T14/V14),"") | X14: =IFERROR(IF(V14=0,"",U14/V14),"") | Y14: =IFERROR(IF(N14=0,"",V14/N14),"") | Z14: =IFERROR(IF(Q14=0,"",(C14+G14)/Q14),"") | AA14: =IFERROR(C14+G14,"") -> 0 | AB14: =IFERROR(IF(AA14=0,"",S14/AA14),"")
A15: Tecpar / BrTecPar | Q15: =IFERROR(C15+D15+G15+H15,"") -> 0 | R15: =IFERROR(C15+D15+E15+F15+G15+H15,"") -> 0 | S15: =IFERROR(I15+J15,"") -> 0 | T15: =IFERROR(Q15-S15,"") -> 0 | U15: =IFERROR(R15-S15,"") -> 0 | V15: =IFERROR(L15+M15,"") -> 0 | W15: =IFERROR(IF(V15=0,"",T15/V15),"") | X15: =IFERROR(IF(V15=0,"",U15/V15),"") | Y15: =IFERROR(IF(N15=0,"",V15/N15),"") | Z15: =IFERROR(IF(Q15=0,"",(C15+G15)/Q15),"") | AA15: =IFERROR(C15+G15,"") -> 0 | AB15: =IFERROR(IF(AA15=0,"",S15/AA15),"")
A16: Algar | Q16: =IFERROR(C16+D16+G16+H16,"") -> 0 | R16: =IFERROR(C16+D16+E16+F16+G16+H16,"") -> 0 | S16: =IFERROR(I16+J16,"") -> 0 | T16: =IFERROR(Q16-S16,"") -> 0 | U16: =IFERROR(R16-S16,"") -> 0 | V16: =IFERROR(L16+M16,"") -> 0 | W16: =IFERROR(IF(V16=0,"",T16/V16),"") | X16: =IFERROR(IF(V16=0,"",U16/V16),"") | Y16: =IFERROR(IF(N16=0,"",V16/N16),"") | Z16: =IFERROR(IF(Q16=0,"",(C16+G16)/Q16),"") | AA16: =IFERROR(C16+G16,"") -> 0 | AB16: =IFERROR(IF(AA16=0,"",S16/AA16),"")
A17: TIM | Q17: =IFERROR(C17+D17+G17+H17,"") -> 0 | R17: =IFERROR(C17+D17+E17+F17+G17+H17,"") -> 0 | S17: =IFERROR(I17+J17,"") -> 0 | T17: =IFERROR(Q17-S17,"") -> 0 | U17: =IFERROR(R17-S17,"") -> 0 | V17: =IFERROR(L17+M17,"") -> 0 | W17: =IFERROR(IF(V17=0,"",T17/V17),"") | X17: =IFERROR(IF(V17=0,"",U17/V17),"") | Y17: =IFERROR(IF(N17=0,"",V17/N17),"") | Z17: =IFERROR(IF(Q17=0,"",(C17+G17)/Q17),"") | AA17: =IFERROR(C17+G17,"") -> 0 | AB17: =IFERROR(IF(AA17=0,"",S17/AA17),"")
... A51: Smartfit | Q51: =IFERROR(C51+D51+G51+H51,"") -> 0 | R51: =IFERROR(C51+D51+E51+F51+G51+H51,"") -> 0 | S51: =IFERROR(I51+J51,"") -> 0 | T51: =IFERROR(Q51-S51,"") -> 0 | U51: =IFERROR(R51-S51,"") -> 0 | V51: =IFERROR(L51+M51,"") -> 0 | W51: =IFERROR(IF(V51=0,"",T51/V51),"") | X51: =IFERROR(IF(V51=0,"",U51/V51),"") | Y51: =IFERROR(IF(N51=0,"",V51/N51),"") | Z51: =IFERROR(IF(Q51=0,"",(C51+G51)/Q51),"") | AA51: =IFERROR(C51+G51,"") -> 0 | AB51: =IFERROR(IF(AA51=0,"",S51/AA51),"")
A52: TOTAL (46 empresas) | C52: =SUM(C6:C51) -> 0 | D52: =SUM(D6:D51) -> 0 | E52: =SUM(E6:E51) -> 0 | F52: =SUM(F6:F51) -> 0 | G52: =SUM(G6:G51) -> 0 | H52: =SUM(H6:H51) -> 0 | I52: =SUM(I6:I51) -> 0 | J52: =SUM(J6:J51) -> 0 | ... V52: =SUM(V6:V51) -> 0 | AA52: =SUM(AA6:AA51) -> 0

Sheet Cronograma de Amortização
A1: CRONOGRAMA DE AMORTIZAÇÃO | POR INSTRUMENTO DE DÍVIDA | UMA LINHA = UM INSTRUMENTO
A2: IDENTIFICAÇÃO | C2: INSTRUMENTO | E2: DADOS DO INSTRUMENTO
A3: Empresa | B3: Setor | C3: Tipo de Instrumento (Debênture / Bond / NP / CRA / CCB / Bancário) | D3: Série / Emissão | E3: Data de Emissão | F3: Saldo Devedor (R$ mm) | G3: Moeda | H3: Vencimento Final | I3: Próx. Amortização (data) | J3: Valor Próx. Amort (R$ mm) | K3: Taxa Contratada | L3: Indexador / Benchmark | M3: Observações / Warning
A4: ⚠ Preencher uma linha por instrumento relevante. Azul = Input manual. Fórmulas automáticas em cinza (dias para vencimento, flag de curto prazo).
A5: Energisa | B5: Energia Elétrica
A8: Cemig | B8: Energia Elétrica
A11: CPFL | B11: Energia Elétrica
A14: Desktop | B14: Telecom / ISP
A17: Unifique | B17: Telecom / ISP
A20: Brisanet | B20: Telecom / ISP
A23: Vero | B23: Telecom / ISP
A26: Alloha | B26: Telecom / ISP
A29: Alares | B29: Telecom / ISP
A32: Tecpar / BrTecPar | B32: Telecom / ISP
A35: Algar | B35: Telecom / ISP
A38: TIM | B38: Telecom
... A140: Smartfit | B140: Fitness / Saúde

Sheet Wall of Maturities
A1: WALL OF MATURITIES | VENCIMENTOS CONSOLIDADOS POR ANO (R$ mm)
A2: Empresa | B2: Setor | C2: 2025 | D2: 2026 | E2: 2027 | F2: 2028 | G2: 2029 | H2: 2030 | I2: 2031 | J2: 2032 | K2: 2033 | L2: 2034 | M2: 2035 | N2: 2036+ | O2: Total
A3: Energisa | B3: Energia Elétrica | O3: =SUM(C3:N3) -> 0
A4: Cemig | B4: Energia Elétrica | O4: =SUM(C4:N4) -> 0
A5: CPFL | B5: Energia Elétrica | O5: =SUM(C5:N5) -> 0
A6: Desktop | B6: Telecom / ISP | O6: =SUM(C6:N6) -> 0
A7: Unifique | B7: Telecom / ISP | O7: =SUM(C7:N7) -> 0
A8: Brisanet | B8: Telecom / ISP | O8: =SUM(C8:N8) -> 0
A9: Vero | B9: Telecom / ISP | O9: =SUM(C9:N9) -> 0
A10: Alloha | B10: Telecom / ISP | O10: =SUM(C10:N10) -> 0
A11: Alares | B11: Telecom / ISP | O11: =SUM(C11:N11) -> 0
A12: Tecpar / BrTecPar | B12: Telecom / ISP | O12: =SUM(C12:N12) -> 0
A13: Algar | B13: Telecom / ISP | O13: =SUM(C13:N13) -> 0
A14: TIM | B14: Telecom | O14: =SUM(C14:N14) -> 0
... A48: Smartfit | B48: Fitness / Saúde | O48: =SUM(C48:N48) -> 0
A49: TOTAL GERAL | C49: =SUM(C3:C48) -> 0 | D49: =SUM(D3:D48) -> 0 | E49: =SUM(E3:E48) -> 0 | F49: =SUM(F3:F48) -> 0 | G49: =SUM(G3:G48) -> 0 | H49: =SUM(H3:H48) -> 0 | I49: =SUM(I3:I48) -> 0 | J49: =SUM(J3:J48) -> 0 | ... O49: =SUM(O3:O48) -> 0
A51: ℹ Preencher com os saldos devedores por ano de vencimento extraídos da aba 'Cronograma de Amortização'. Considerar apenas amortizações de principal.

Sheet Covenants & Capex
A1: COVENANTS FINANCEIROS | GUIDANCE DE CAPEX | M&A RECENTE
A2: Empresa | B2: Setor | C2: Instrumento / Debenturista | D2: Covenant: DL/ EBITDA — Limite | E2: Covenant: Outro Indicador | F2: Headroom Atual | G2: Guidance Capex 12 meses (R$ mm) | H2: Guidance Capex 24 meses (R$ mm) | I2: M&A Anunciado (Alvo / Valor) | J2: Impacto Alavancagem | K2: Observações
A3: Energisa | B3: Energia Elétrica
A4: Cemig | B4: Energia Elétrica
A5: CPFL | B5: Energia Elétrica
A6: Desktop | B6: Telecom / ISP
A7: Unifique | B7: Telecom / ISP
A8: Brisanet | B8: Telecom / ISP
A9: Vero | B9: Telecom / ISP
A10: Alloha | B10: Telecom / ISP
A11: Alares | B11: Telecom / ISP
A12: Tecpar / BrTecPar | B12: Telecom / ISP
A13: Algar | B13: Telecom / ISP
A14: TIM | B14: Telecom
... A48: Smartfit | B48: Fitness / Saúde

Sheet Fontes — RI
A1: FONTES | SITES DE RELAÇÕES COM INVESTIDORES
A2: Links para os portais de RI das empresas em cobertura. Verificar release do último trimestre e/ou apresentação de resultados para preenchimento das abas.
A3: Empresa | B3: Ticker | C3: Setor | D3: Link Portal RI | E3: Última Atualização / Nota
A4: ▌ ENERGIA ELÉTRICA
A5: Energisa | B5: ENGI11 | C5: Energia Elétrica | D5: https://www.energisa.com.br/Paginas/Informacoes/Investidores.aspx
A6: Cemig | B6: CMIG4 | C6: Energia Elétrica | D6: https://ri.cemig.com.br/
A7: CPFL | B7: CPFE3 | C7: Energia Elétrica | D7: https://ri.cpfl.com.br/
A8: ▌ TELECOM / ISP
A9: Desktop | B9: DESK3 | C9: Telecom / ISP | D9: https://ri.desktop.com.br/
A10: Unifique | B10: FIQE3 | C10: Telecom / ISP | D10: https://ri.unifique.com.br/
A11: Brisanet | B11: BRIT3 | C11: Telecom / ISP | D11: https://ri.brisanet.com.br/
A12: Vero | B12: N/A | C12: Telecom / ISP | D12: https://www.vero.net.br/ri
A13: Alloha | B13: N/A | C13: Telecom / ISP | D13: https://www.allohari.com/
A14: Alares | B14: N/A | C14: Telecom / ISP | D14: https://ri.alaresinternet.com.br/
A15: Tecpar / BrTecPar | B15: N/A | C15: Telecom / ISP | D15: https://ri.brasiltecpar.com.br/
A16: Algar | B16: ALGT3 | C16: Telecom / ISP | D16: https://ri.algar.com.br/
A17: ▌ TELECOM
A18: TIM | B18: TIMS3 | C18: Telecom | D18: https://ri.tim.com.br/
A19: ▌ LOCAÇÃO / TRANSPORTE
A20: Vamos | B20: VAMO3 | C20: Locação / Transporte | D20: https://ri.vamos.com.br/
A21: Movida | B21: MOVI3 | C21: Locação / Transporte | D21: https://ri.movida.com.br/
A22: ▌ LOGÍSTICA
A23: JSL | B23: JSLG3 | C23: Logística | D23: https://ri.jsl.com.br/
A24: ▌ INFRAESTRUTURA / RODOV.
A25: Ecorodovias | B25: ECOR3 | C25: Infraestrutura / Rodov. | D25: https://ri.ecorodovias.com.br/
A26: ▌ PORTO / LOGÍSTICA
A27: Santos Brasil | B27: STBP3 | C27: Porto / Logística | D27: https://ri.santosbrasil.com.br/
A28: ▌ SANEAMENTO
A29: Copasa | B29: CSMG3 | C29: Saneamento | D29: https://ri.copasa.com.br/
A30: Sanepar | B30: SAPR11 | C30: Saneamento | D30: https://www.sanepar.com.br/ri
A31: Saneago | B31: SAAG4 | C31: Saneamento | D31: https://ri.saneago.com.br/
A32: ▌ LOGÍSTICA / TRANSPORTE
A33: Vix | B33: VIIA3 | C33: Logística / Transporte | D33: https://ri.vix.com.br/
A34: ▌ LOCAÇÃO
A35: Armac | B35: ARML3 | C35: Locação | D35: https://ri.armac.com.br/
A36: Unidas | B36: LCAM3 | C36: Locação | D36: https://ri.unidas.com.br/
A37: ▌ LOCAÇÃO / INDÚSTRIA
A38: Mills | B38: MILS3 | C38: Locação / Indústria | D38: https://ri.mills.com.br/
A39: ▌ SERVIÇOS INDUSTRIAIS
A40: Priner | B40: PRNR3 | C40: Serviços Industriais | D40: https://ri.priner.com.br/
...

Sheet Notas Metodológicas
A1: NOTAS METODOLÓGICAS | DEFINIÇÕES E CONVENÇÕES
A2: Campo / Métrica | B2: Definição e Metodologia
A3: PERÍODO BASE | B3: Último quarter com LTM (Last Twelve Months) divulgado. Ajustar label na aba 'Painel de Crédito' conforme publicação de resultados.
A4: DÍVIDA BRUTA | B4: Total de dívidas financeiras onerosas: debêntures, bonds, CRAs, NPs, CCBs, empréstimos bancários e arrendamentos (IFRS 16 a critério do analista — indicar se incluído).
A5: CAIXA | B5: Caixa e equivalentes + aplicações financeiras de curto prazo. Excluir restritos.
A6: DÍVIDA LÍQUIDA | B6: Dívida Bruta – Caixa. Fórmula automática na planilha. Se negativo, indica posição de caixa líquido.
A7: EBITDA LTM | B7: EBITDA ajustado LTM conforme reportado pela companhia (preferir EBITDA recorrente/ajustado divulgado no release). Se não divulgado, calcular: EBIT + D&A.
A8: DL / EBITDA | B8: Alavancagem financeira. Calculado automaticamente. Referência: >4,0x = elevado; 2,0-4,0x = moderado; <2,0x = baixo (parâmetros setoriais variam).
A9: EBITDA / DESP. FIN. | B9: Índice de cobertura de juros (ICJ). Input manual. Referência: <2,0x = zona de atenção; >3,0x = confortável.
A10: CUSTO MÉDIO | B10: Custo médio ponderado da dívida (% a.a.), conforme disclosure da companhia ou calculado via juros pagos / saldo médio. Indicar se CDI+spread ou % CDI.
A11: DURATION MÉDIA | B11: Prazo médio ponderado da dívida em anos, considerando fluxos de principal e juros, ou conforme disclosure da empresa.
A12: % CURTO PRAZO | B12: Parcela da dívida bruta vencendo em até 12 meses / dívida bruta total.
A13: DÍVIDA CP | B13: Saldo da dívida com vencimento em até 12 meses (circulante). Fonte: notas explicativas.
... A22: ATUALIZAÇÃO | B22: Recomendado atualizar a cada ciclo de resultados (trimestral). Registrar data de atualização na col. 'Última Atualização' da aba Fontes—RI.
