Workbook

Sheet Painel de Crédito
A1: DCM CREDIT SCREENING | ANÁLISE DE OPORTUNIDADES DE DÍVIDA | BASE: ÚLTIMO QUARTER LTM DIVULGADO
A2: IDENTIFICAÇÃO | D2: INDICADORES DE CRÉDITO E LIQUIDEZ | O2: TRIGGERS / CATALISADORES
A3: Empresa | B3: Ticker | C3: Setor | D3: Dívida Bruta (R$ mm) | E3: Caixa (R$ mm) | F3: Dívida Líquida (R$ mm) | G3: EBITDA LTM (R$ mm) | H3: Dív Líq / EBITDA (x) | I3: EBITDA / Desp Fin (x) | J3: Custo Médio Dívida % aa | K3: Duration Média (anos) | L3: % CP Dívida | M3: Dívida CP (R$ mm) | N3: Caixa / Dívida CP (x) | O3: Covenants Financeiros | P3: Guidance Capex 12-24m | Q3: M&A Recente | R3: Observações / Oportunidade
A4: ⚠ Convenção de cores de texto: Azul = Input manual (hardcode) | Preto = Fórmula | Verde = Link cross-sheet | Amarelo = Atenção / Atualizar
A5: Energisa | B5: ENGI11 | C5: Energia Elétrica | D5: ='Inputs — DFs'!Q6 | E5: ='Inputs — DFs'!S6 | F5: =IF(AND(D5<>"",E5<>""),D5-E5,"") | G5: ='Inputs — DFs'!V6 | H5: =IF(AND(G5<>"",((G5)<>0)),F5/G5,"") | I5: ='Inputs — DFs'!Y6 | L5: ='Inputs — DFs'!Z6 | M5: ='Inputs — DFs'!AA6 | N5: =IF(AND(M5<>"",((M5)<>0)),E5/M5,"")
A6: Cemig | B6: CMIG4 | C6: Energia Elétrica | D6: ='Inputs — DFs'!Q7 | E6: ='Inputs — DFs'!S7 | F6: =IF(AND(D6<>"",E6<>""),D6-E6,"") | G6: ='Inputs — DFs'!V7 | H6: =IF(AND(G6<>"",((G6)<>0)),F6/G6,"") | I6: ='Inputs — DFs'!Y7 | L6: ='Inputs — DFs'!Z7 | M6: ='Inputs — DFs'!AA7 | N6: =IF(AND(M6<>"",((M6)<>0)),E6/M6,"")
A7: CPFL | B7: CPFE3 | C7: Energia Elétrica | D7: ='Inputs — DFs'!Q8 | E7: ='Inputs — DFs'!S8 | F7: =IF(AND(D7<>"",E7<>""),D7-E7,"") | G7: ='Inputs — DFs'!V8 | H7: =IF(AND(G7<>"",((G7)<>0)),F7/G7,"") | I7: ='Inputs — DFs'!Y8 | L7: ='Inputs — DFs'!Z8 | M7: ='Inputs — DFs'!AA8 | N7: =IF(AND(M7<>"",((M7)<>0)),E7/M7,"")
A8: Desktop | B8: DESK3 | C8: Telecom / ISP | D8: ='Inputs — DFs'!Q9 | E8: ='Inputs — DFs'!S9 | F8: =IF(AND(D8<>"",E8<>""),D8-E8,"") | G8: ='Inputs — DFs'!V9 | H8: =IF(AND(G8<>"",((G8)<>0)),F8/G8,"") | I8: ='Inputs — DFs'!Y9 | L8: ='Inputs — DFs'!Z9 | M8: ='Inputs — DFs'!AA9 | N8: =IF(AND(M8<>"",((M8)<>0)),E8/M8,"")
A9: Unifique | B9: FIQE3 | C9: Telecom / ISP | D9: ='Inputs — DFs'!Q10 | E9: ='Inputs — DFs'!S10 | F9: =IF(AND(D9<>"",E9<>""),D9-E9,"") | G9: ='Inputs — DFs'!V10 | H9: =IF(AND(G9<>"",((G9)<>0)),F9/G9,"") | I9: ='Inputs — DFs'!Y10 | L9: ='Inputs — DFs'!Z10 | M9: ='Inputs — DFs'!AA10 | N9: =IF(AND(M9<>"",((M9)<>0)),E9/M9,"")
A10: Brisanet | B10: BRIT3 | C10: Telecom / ISP | D10: ='Inputs — DFs'!Q11 | E10: ='Inputs — DFs'!S11 | F10: =IF(AND(D10<>"",E10<>""),D10-E10,"") | G10: ='Inputs — DFs'!V11 | H10: =IF(AND(G10<>"",((G10)<>0)),F10/G10,"") | I10: ='Inputs — DFs'!Y11 | L10: ='Inputs — DFs'!Z11 | M10: ='Inputs — DFs'!AA11 | N10: =IF(AND(M10<>"",((M10)<>0)),E10/M10,"")
A11: Vero | B11: N/A | C11: Telecom / ISP | D11: ='Inputs — DFs'!Q12 | E11: ='Inputs — DFs'!S12 | F11: =IF(AND(D11<>"",E11<>""),D11-E11,"") | G11: ='Inputs — DFs'!V12 | H11: =IF(AND(G11<>"",((G11)<>0)),F11/G11,"") | I11: ='Inputs — DFs'!Y12 | L11: ='Inputs — DFs'!Z12 | M11: ='Inputs — DFs'!AA12 | N11: =IF(AND(M11<>"",((M11)<>0)),E11/M11,"")
A12: Alloha | B12: N/A | C12: Telecom / ISP | D12: ='Inputs — DFs'!Q13 | E12: ='Inputs — DFs'!S13 | F12: =IF(AND(D12<>"",E12<>""),D12-E12,"") | G12: ='Inputs — DFs'!V13 | H12: =IF(AND(G12<>"",((G12)<>0)),F12/G12,"") | I12: ='Inputs — DFs'!Y13 | L12: ='Inputs — DFs'!Z13 | M12: ='Inputs — DFs'!AA13 | N12: =IF(AND(M12<>"",((M12)<>0)),E12/M12,"")
A13: Alares | B13: N/A | C13: Telecom / ISP | D13: ='Inputs — DFs'!Q14 | E13: ='Inputs — DFs'!S14 | F13: =IF(AND(D13<>"",E13<>""),D13-E13,"") | G13: ='Inputs — DFs'!V14 | H13: =IF(AND(G13<>"",((G13)<>0)),F13/G13,"") | I13: ='Inputs — DFs'!Y14 | L13: ='Inputs — DFs'!Z14 | M13: ='Inputs — DFs'!AA14 | N13: =IF(AND(M13<>"",((M13)<>0)),E13/M13,"")
A14: Tecpar / BrTecPar | B14: N/A | C14: Telecom / ISP | D14: ='Inputs — DFs'!Q15 | E14: ='Inputs — DFs'!S15 | F14: =IF(AND(D14<>"",E14<>""),D14-E14,"") | G14: ='Inputs — DFs'!V15 | H14: =IF(AND(G14<>"",((G14)<>0)),F14/G14,"") | I14: ='Inputs — DFs'!Y15 | L14: ='Inputs — DFs'!Z15 | M14: ='Inputs — DFs'!AA15 | N14: =IF(AND(M14<>"",((M14)<>0)),E14/M14,"")
A15: Algar | B15: ALGT3 | C15: Telecom / ISP | D15: ='Inputs — DFs'!Q16 | E15: ='Inputs — DFs'!S16 | F15: =IF(AND(D15<>"",E15<>""),D15-E15,"") | G15: ='Inputs — DFs'!V16 | H15: =IF(AND(G15<>"",((G15)<>0)),F15/G15,"") | I15: ='Inputs — DFs'!Y16 | L15: ='Inputs — DFs'!Z16 | M15: ='Inputs — DFs'!AA16 | N15: =IF(AND(M15<>"",((M15)<>0)),E15/M15,"")
A16: TIM | B16: TIMS3 | C16: Telecom | D16: ='Inputs — DFs'!Q17 | E16: ='Inputs — DFs'!S17 | F16: =IF(AND(D16<>"",E16<>""),D16-E16,"") | G16: ='Inputs — DFs'!V17 | H16: =IF(AND(G16<>"",((G16)<>0)),F16/G16,"") | I16: ='Inputs — DFs'!Y17 | L16: ='Inputs — DFs'!Z17 | M16: ='Inputs — DFs'!AA17 | N16: =IF(AND(M16<>"",((M16)<>0)),E16/M16,"")
... A50: Smartfit | B50: SMFT3 | C50: Fitness / Saúde | D50: ='Inputs — DFs'!Q51 | E50: ='Inputs — DFs'!S51 | F50: =IF(AND(D50<>"",E50<>""),D50-E50,"") | G50: ='Inputs — DFs'!V51 | H50: =IF(AND(G50<>"",((G50)<>0)),F50/G50,"") | I50: ='Inputs — DFs'!Y51 | L50: ='Inputs — DFs'!Z51 | M50: ='Inputs — DFs'!AA51 | N50: =IF(AND(M50<>"",((M50)<>0)),E50/M50,"")
A51: TOTAL (46 empresas) | D51: =SUM(D5:D50) | E51: =SUM(E5:E50) | F51: =SUM(F5:F50) | G51: =SUM(G5:G50) | M51: =SUM(M5:M50)

Sheet Inputs — DFs
A1: INPUTS — DEMONSTRAÇÕES FINANCEIRAS | EXTRAÇÃO DIRETA DAS NOTAS EXPLICATIVAS (DFP / ITR)
A2: Azul = input manual (hardcode extraído da DF) | Preto = fórmula automática | Verde = valor exportado para 'Painel de Crédito' | Cinza = calculado nesta aba
A3: IDENTIFICAÇÃO | C3: BALANÇO — DÍVIDA (R$ mm) | I3: BALANÇO — CAIXA (R$ mm) | K3: P&L LTM (R$ mm) | Q3: DÍVIDA BRUTA CALC. | S3: CAIXA / DÍV. LÍQUIDA | V3: EBITDA | W3: DL/EBITDA | Y3: ICJ | Z3: LIQUIDEZ CP
A4: ℹ IFRS 16 (arrendamentos): preencher cols E e F se quiser comparar alavancagem com e sem leasing. Cols Q e W excluem IFRS16; cols R e X incluem. Deixar em branco se não aplicável.
A5: Empresa | B5: Período (ex: 4T24 LTM) | C5: Emp. & Fin. CP | D5: Emp. & Fin. LP | E5: Arrendam. CP (IFRS16) | F5: Arrendam. LP (IFRS16) | G5: Outros Passivos Fin. CP | H5: Outros Passivos Fin. LP | I5: Caixa e Equivalentes | J5: Aplicações Financ. CP | K5: Receita Líquida LTM | L5: EBIT LTM | M5: D&A LTM | N5: Desp. Financ. Bruta | O5: Rec. Financ. LTM | P5: Capex LTM | Q5: Dív. Bruta (sem IFRS16) | R5: Dív. Bruta (com IFRS16) | S5: Caixa Total | T5: Dív. Líq. (sem IFRS16) | U5: Dív. Líq. (com IFRS16) | V5: EBITDA LTM | W5: DL/EBITDA (sem IFRS16) | X5: DL/EBITDA (com IFRS16) | Y5: EBITDA / Desp Fin | Z5: % CP (sem IFRS16) | AA5: Dív. CP (sem IFRS16) | AB5: Caixa / Dív. CP
A6: Energisa | Q6: =IFERROR(C6+D6+G6+H6,"") | R6: =IFERROR(C6+D6+E6+F6+G6+H6,"") | S6: =IFERROR(I6+J6,"") | T6: =IFERROR(Q6-S6,"") | U6: =IFERROR(R6-S6,"") | V6: =IFERROR(L6+M6,"") | W6: =IFERROR(IF(V6=0,"",T6/V6),"") | X6: =IFERROR(IF(V6=0,"",U6/V6),"") | Y6: =IFERROR(IF(N6=0,"",V6/N6),"") | Z6: =IFERROR(IF(Q6=0,"",(C6+G6)/Q6),"") | AA6: =IFERROR(C6+G6,"") | AB6: =IFERROR(IF(AA6=0,"",S6/AA6),"")
A7: Cemig | Q7: =IFERROR(C7+D7+G7+H7,"") | R7: =IFERROR(C7+D7+E7+F7+G7+H7,"") | S7: =IFERROR(I7+J7,"") | T7: =IFERROR(Q7-S7,"") | U7: =IFERROR(R7-S7,"") | V7: =IFERROR(L7+M7,"") | W7: =IFERROR(IF(V7=0,"",T7/V7),"") | X7: =IFERROR(IF(V7=0,"",U7/V7),"") | Y7: =IFERROR(IF(N7=0,"",V7/N7),"") | Z7: =IFERROR(IF(Q7=0,"",(C7+G7)/Q7),"") | AA7: =IFERROR(C7+G7,"") | AB7: =IFERROR(IF(AA7=0,"",S7/AA7),"")
A8: CPFL | Q8: =IFERROR(C8+D8+G8+H8,"") | R8: =IFERROR(C8+D8+E8+F8+G8+H8,"") | S8: =IFERROR(I8+J8,"") | T8: =IFERROR(Q8-S8,"") | U8: =IFERROR(R8-S8,"") | V8: =IFERROR(L8+M8,"") | W8: =IFERROR(IF(V8=0,"",T8/V8),"") | X8: =IFERROR(IF(V8=0,"",U8/V8),"") | Y8: =IFERROR(IF(N8=0,"",V8/N8),"") | Z8: =IFERROR(IF(Q8=0,"",(C8+G8)/Q8),"") | AA8: =IFERROR(C8+G8,"") | AB8: =IFERROR(IF(AA8=0,"",S8/AA8),"")
A9: Desktop | Q9: =IFERROR(C9+D9+G9+H9,"") | R9: =IFERROR(C9+D9+E9+F9+G9+H9,"") | S9: =IFERROR(I9+J9,"") | T9: =IFERROR(Q9-S9,"") | U9: =IFERROR(R9-S9,"") | V9: =IFERROR(L9+M9,"") | W9: =IFERROR(IF(V9=0,"",T9/V9),"") | X9: =IFERROR(IF(V9=0,"",U9/V9),"") | Y9: =IFERROR(IF(N9=0,"",V9/N9),"") | Z9: =IFERROR(IF(Q9=0,"",(C9+G9)/Q9),"") | AA9: =IFERROR(C9+G9,"") | AB9: =IFERROR(IF(AA9=0,"",S9/AA9),"")
A10: Unifique | Q10: =IFERROR(C10+D10+G10+H10,"") | R10: =IFERROR(C10+D10+E10+F10+G10+H10,"") | S10: =IFERROR(I10+J10,"") | T10: =IFERROR(Q10-S10,"") | U10: =IFERROR(R10-S10,"") | V10: =IFERROR(L10+M10,"") | W10: =IFERROR(IF(V10=0,"",T10/V10),"") | X10: =IFERROR(IF(V10=0,"",U10/V10),"") | Y10: =IFERROR(IF(N10=0,"",V10/N10),"") | Z10: =IFERROR(IF(Q10=0,"",(C10+G10)/Q10),"") | AA10: =IFERROR(C10+G10,"") | AB10: =IFERROR(IF(AA10=0,"",S10/AA10),"")
A11: Brisanet | Q11: =IFERROR(C11+D11+G11+H11,"") | R11: =IFERROR(C11+D11+E11+F11+G11+H11,"") | S11: =IFERROR(I11+J11,"") | T11: =IFERROR(Q11-S11,"") | U11: =IFERROR(R11-S11,"") | V11: =IFERROR(L11+M11,"") | W11: =IFERROR(IF(V11=0,"",T11/V11),"") | X11: =IFERROR(IF(V11=0,"",U11/V11),"") | Y11: =IFERROR(IF(N11=0,"",V11/N11),"") | Z11: =IFERROR(IF(Q11=0,"",(C11+G11)/Q11),"") | AA11: =IFERROR(C11+G11,"") | AB11: =IFERROR(IF(AA11=0,"",S11/AA11),"")
A12: Vero | Q12: =IFERROR(C12+D12+G12+H12,"") | R12: =IFERROR(C12+D12+E12+F12+G12+H12,"") | S12: =IFERROR(I12+J12,"") | T12: =IFERROR(Q12-S12,"") | U12: =IFERROR(R12-S12,"") | V12: =IFERROR(L12+M12,"") | W12: =IFERROR(IF(V12=0,"",T12/V12),"") | X12: =IFERROR(IF(V12=0,"",U12/V12),"") | Y12: =IFERROR(IF(N12=0,"",V12/N12),"") | Z12: =IFERROR(IF(Q12=0,"",(C12+G12)/Q12),"") | AA12: =IFERROR(C12+G12,"") | AB12: =IFERROR(IF(AA12=0,"",S12/AA12),"")
A13: Alloha | Q13: =IFERROR(C13+D13+G13+H13,"") | R13: =IFERROR(C13+D13+E13+F13+G13+H13,"") | S13: =IFERROR(I13+J13,"") | T13: =IFERROR(Q13-S13,"") | U13: =IFERROR(R13-S13,"") | V13: =IFERROR(L13+M13,"") | W13: =IFERROR(IF(V13=0,"",T13/V13),"") | X13: =IFERROR(IF(V13=0,"",U13/V13),"") | Y13: =IFERROR(IF(N13=0,"",V13/N13),"") | Z13: =IFERROR(IF(Q13=0,"",(C13+G13)/Q13),"") | AA13: =IFERROR(C13+G13,"") | AB13: =IFERROR(IF(AA13=0,"",S13/AA13),"")
A14: Alares | Q14: =IFERROR(C14+D14+G14+H14,"") | R14: =IFERROR(C14+D14+E14+F14+G14+H14,"") | S14: =IFERROR(I14+J14,"") | T14: =IFERROR(Q14-S14,"") | U14: =IFERROR(R14-S14,"") | V14: =IFERROR(L14+M14,"") | W14: =IFERROR(IF(V14=0,"",T14/V14),"") | X14: =IFERROR(IF(V14=0,"",U14/V14),"") | Y14: =IFERROR(IF(N14=0,"",V14/N14),"") | Z14: =IFERROR(IF(Q14=0,"",(C14+G14)/Q14),"") | AA14: =IFERROR(C14+G14,"") | AB14: =IFERROR(IF(AA14=0,"",S14/AA14),"")
A15: Tecpar / BrTecPar | Q15: =IFERROR(C15+D15+G15+H15,"") | R15: =IFERROR(C15+D15+E15+F15+G15+H15,"") | S15: =IFERROR(I15+J15,"") | T15: =IFERROR(Q15-S15,"") | U15: =IFERROR(R15-S15,"") | V15: =IFERROR(L15+M15,"") | W15: =IFERROR(IF(V15=0,"",T15/V15),"") | X15: =IFERROR(IF(V15=0,"",U15/V15),"") | Y15: =IFERROR(IF(N15=0,"",V15/N15),"") | Z15: =IFERROR(IF(Q15=0,"",(C15+G15)/Q15),"") | AA15: =IFERROR(C15+G15,"") | AB15: =IFERROR(IF(AA15=0,"",S15/AA15),"")
A16: Algar | Q16: =IFERROR(C16+D16+G16+H16,"") | R16: =IFERROR(C16+D16+E16+F16+G16+H16,"") | S16: =IFERROR(I16+J16,"") | T16: =IFERROR(Q16-S16,"") | U16: =IFERROR(R16-S16,"") | V16: =IFERROR(L16+M16,"") | W16: =IFERROR(IF(V16=0,"",T16/V16),"") | X16: =IFERROR(IF(V16=0,"",U16/V16),"") | Y16: =IFERROR(IF(N16=0,"",V16/N16),"") | Z16: =IFERROR(IF(Q16=0,"",(C16+G16)/Q16),"") | AA16: =IFERROR(C16+G16,"") | AB16: =IFERROR(IF(AA16=0,"",S16/AA16),"")
A17: TIM | Q17: =IFERROR(C17+D17+G17+H17,"") | R17: =IFERROR(C17+D17+E17+F17+G17+H17,"") | S17: =IFERROR(I17+J17,"") | T17: =IFERROR(Q17-S17,"") | U17: =IFERROR(R17-S17,"") | V17: =IFERROR(L17+M17,"") | W17: =IFERROR(IF(V17=0,"",T17/V17),"") | X17: =IFERROR(IF(V17=0,"",U17/V17),"") | Y17: =IFERROR(IF(N17=0,"",V17/N17),"") | Z17: =IFERROR(IF(Q17=0,"",(C17+G17)/Q17),"") | AA17: =IFERROR(C17+G17,"") | AB17: =IFERROR(IF(AA17=0,"",S17/AA17),"")
... A40: BRF | Q40: =IFERROR(C40+D40+G40+H40,"") | R40: =IFERROR(C40+D40+E40+F40+G40+H40,"") | S40: =IFERROR(I40+J40,"") | T40: =IFERROR(Q40-S40,"") | U40: =IFERROR(R40-S40,"") | V40: =IFERROR(L40+M40,"") | W40: =IFERROR(IF(V40=0,"",T40/V40),"") | X40: =IFERROR(IF(V40=0,"",U40/V40),"") | Y40: =IFERROR(IF(N40=0,"",V40/N40),"") | Z40: =IFERROR(IF(Q40=0,"",(C40+G40)/Q40),"") | AA40: =IFERROR(C40+G40,"") | AB40: =IFERROR(IF(AA40=0,"",S40/AA40),"")
A41: Ânima | B41: 1T26 LTM | C41: 474.8 | D41: 4024.3 | E41: 132.6 | F41: 1243.3 | I41: 105.1 | J41: 1627.1 | K41: 4109.4 | L41: 1023 | M41: 420.8 | N41: 887.3 | O41: 272.7 | P41: 220.8 | Q41: =IFERROR(C41+D41+G41+H41,"") | R41: =IFERROR(C41+D41+E41+F41+G41+H41,"") | S41: =IFERROR(I41+J41,"") | T41: =IFERROR(Q41-S41,"") | U41: =IFERROR(R41-S41,"") | V41: =IFERROR(L41+M41,"") | W41: =IFERROR(IF(V41=0,"",T41/V41),"") | X41: =IFERROR(IF(V41=0,"",U41/V41),"") | Y41: =IFERROR(IF(N41=0,"",V41/N41),"") | Z41: =IFERROR(IF(Q41=0,"",(C41+G41)/Q41),"") | AA41: =IFERROR(C41+G41,"") | AB41: =IFERROR(IF(AA41=0,"",S41/AA41),"")
A42: Inspiralli | Q42: =IFERROR(C42+D42+G42+H42,"") | R42: =IFERROR(C42+D42+E42+F42+G42+H42,"") | S42: =IFERROR(I42+J42,"") | T42: =IFERROR(Q42-S42,"") | U42: =IFERROR(R42-S42,"") | V42: =IFERROR(L42+M42,"") | W42: =IFERROR(IF(V42=0,"",T42/V42),"") | X42: =IFERROR(IF(V42=0,"",U42/V42),"") | Y42: =IFERROR(IF(N42=0,"",V42/N42),"") | Z42: =IFERROR(IF(Q42=0,"",(C42+G42)/Q42),"") | AA42: =IFERROR(C42+G42,"") | AB42: =IFERROR(IF(AA42=0,"",S42/AA42),"")
A43: Yduqs | B43: 1T26 LTM | C43: 582.3 | D43: 3184.4 | E43: 264.6 | F43: 1338.3 | I43: 571.4 | J43: 509.8 | K43: 5543.4 | L43: 822.6 | M43: 804.8 | N43: 937 | O43: 372.6 | P43: 460.3 | Q43: =IFERROR(C43+D43+G43+H43,"") | R43: =IFERROR(C43+D43+E43+F43+G43+H43,"") | S43: =IFERROR(I43+J43,"") | T43: =IFERROR(Q43-S43,"") | U43: =IFERROR(R43-S43,"") | V43: =IFERROR(L43+M43,"") | W43: =IFERROR(IF(V43=0,"",T43/V43),"") | X43: =IFERROR(IF(V43=0,"",U43/V43),"") | Y43: =IFERROR(IF(N43=0,"",V43/N43),"") | Z43: =IFERROR(IF(Q43=0,"",(C43+G43)/Q43),"") | AA43: =IFERROR(C43+G43,"") | AB43: =IFERROR(IF(AA43=0,"",S43/AA43),"")
A44: Afya | B44: 1T26 LTM | C44: 132.1 | D44: 1992.4 | E44: 55.5 | F44: 1021.6 | G44: 57.3 | H44: 302.3 | I44: 1332.9 | K44: 3773.6 | L44: 1234.2 | M44: 374.6 | P44: 293 | Q44: =IFERROR(C44+D44+G44+H44,"") | R44: =IFERROR(C44+D44+E44+F44+G44+H44,"") | S44: =IFERROR(I44+J44,"") | T44: =IFERROR(Q44-S44,"") | U44: =IFERROR(R44-S44,"") | V44: =IFERROR(L44+M44,"") | W44: =IFERROR(IF(V44=0,"",T44/V44),"") | X44: =IFERROR(IF(V44=0,"",U44/V44),"") | Y44: =IFERROR(IF(N44=0,"",V44/N44),"") | Z44: =IFERROR(IF(Q44=0,"",(C44+G44)/Q44),"") | AA44: =IFERROR(C44+G44,"") | AB44: =IFERROR(IF(AA44=0,"",S44/AA44),"")
A45: Cruzeiro do Sul | Q45: =IFERROR(C45+D45+G45+H45,"") | R45: =IFERROR(C45+D45+E45+F45+G45+H45,"") | S45: =IFERROR(I45+J45,"") | T45: =IFERROR(Q45-S45,"") | U45: =IFERROR(R45-S45,"") | V45: =IFERROR(L45+M45,"") | W45: =IFERROR(IF(V45=0,"",T45/V45),"") | X45: =IFERROR(IF(V45=0,"",U45/V45),"") | Y45: =IFERROR(IF(N45=0,"",V45/N45),"") | Z45: =IFERROR(IF(Q45=0,"",(C45+G45)/Q45),"") | AA45: =IFERROR(C45+G45,"") | AB45: =IFERROR(IF(AA45=0,"",S45/AA45),"")
A46: Cogna | Q46: =IFERROR(C46+D46+G46+H46,"") | R46: =IFERROR(C46+D46+E46+F46+G46+H46,"") | S46: =IFERROR(I46+J46,"") | T46: =IFERROR(Q46-S46,"") | U46: =IFERROR(R46-S46,"") | V46: =IFERROR(L46+M46,"") | W46: =IFERROR(IF(V46=0,"",T46/V46),"") | X46: =IFERROR(IF(V46=0,"",U46/V46),"") | Y46: =IFERROR(IF(N46=0,"",V46/N46),"") | Z46: =IFERROR(IF(Q46=0,"",(C46+G46)/Q46),"") | AA46: =IFERROR(C46+G46,"") | AB46: =IFERROR(IF(AA46=0,"",S46/AA46),"")
A47: Vitru | Q47: =IFERROR(C47+D47+G47+H47,"") | R47: =IFERROR(C47+D47+E47+F47+G47+H47,"") | S47: =IFERROR(I47+J47,"") | T47: =IFERROR(Q47-S47,"") | U47: =IFERROR(R47-S47,"") | V47: =IFERROR(L47+M47,"") | W47: =IFERROR(IF(V47=0,"",T47/V47),"") | X47: =IFERROR(IF(V47=0,"",U47/V47),"") | Y47: =IFERROR(IF(N47=0,"",V47/N47),"") | Z47: =IFERROR(IF(Q47=0,"",(C47+G47)/Q47),"") | AA47: =IFERROR(C47+G47,"") | AB47: =IFERROR(IF(AA47=0,"",S47/AA47),"")
A48: Ser Educacional | Q48: =IFERROR(C48+D48+G48+H48,"") | R48: =IFERROR(C48+D48+E48+F48+G48+H48,"") | S48: =IFERROR(I48+J48,"") | T48: =IFERROR(Q48-S48,"") | U48: =IFERROR(R48-S48,"") | V48: =IFERROR(L48+M48,"") | W48: =IFERROR(IF(V48=0,"",T48/V48),"") | X48: =IFERROR(IF(V48=0,"",U48/V48),"") | Y48: =IFERROR(IF(N48=0,"",V48/N48),"") | Z48: =IFERROR(IF(Q48=0,"",(C48+G48)/Q48),"") | AA48: =IFERROR(C48+G48,"") | AB48: =IFERROR(IF(AA48=0,"",S48/AA48),"")
A49: Salta Educação | Q49: =IFERROR(C49+D49+G49+H49,"") | R49: =IFERROR(C49+D49+E49+F49+G49+H49,"") | S49: =IFERROR(I49+J49,"") | T49: =IFERROR(Q49-S49,"") | U49: =IFERROR(R49-S49,"") | V49: =IFERROR(L49+M49,"") | W49: =IFERROR(IF(V49=0,"",T49/V49),"") | X49: =IFERROR(IF(V49=0,"",U49/V49),"") | Y49: =IFERROR(IF(N49=0,"",V49/N49),"") | Z49: =IFERROR(IF(Q49=0,"",(C49+G49)/Q49),"") | AA49: =IFERROR(C49+G49,"") | AB49: =IFERROR(IF(AA49=0,"",S49/AA49),"")
A50: Inspira | Q50: =IFERROR(C50+D50+G50+H50,"") | R50: =IFERROR(C50+D50+E50+F50+G50+H50,"") | S50: =IFERROR(I50+J50,"") | T50: =IFERROR(Q50-S50,"") | U50: =IFERROR(R50-S50,"") | V50: =IFERROR(L50+M50,"") | W50: =IFERROR(IF(V50=0,"",T50/V50),"") | X50: =IFERROR(IF(V50=0,"",U50/V50),"") | Y50: =IFERROR(IF(N50=0,"",V50/N50),"") | Z50: =IFERROR(IF(Q50=0,"",(C50+G50)/Q50),"") | AA50: =IFERROR(C50+G50,"") | AB50: =IFERROR(IF(AA50=0,"",S50/AA50),"")
A51: Smartfit | Q51: =IFERROR(C51+D51+G51+H51,"") | R51: =IFERROR(C51+D51+E51+F51+G51+H51,"") | S51: =IFERROR(I51+J51,"") | T51: =IFERROR(Q51-S51,"") | U51: =IFERROR(R51-S51,"") | V51: =IFERROR(L51+M51,"") | W51: =IFERROR(IF(V51=0,"",T51/V51),"") | X51: =IFERROR(IF(V51=0,"",U51/V51),"") | Y51: =IFERROR(IF(N51=0,"",V51/N51),"") | Z51: =IFERROR(IF(Q51=0,"",(C51+G51)/Q51),"") | AA51: =IFERROR(C51+G51,"") | AB51: =IFERROR(IF(AA51=0,"",S51/AA51),"")
A52: TOTAL (46 empresas) | C52: =SUM(C6:C51) | D52: =SUM(D6:D51) | E52: =SUM(E6:E51) | F52: =SUM(F6:F51) | G52: =SUM(G6:G51) | H52: =SUM(H6:H51) | I52: =SUM(I6:I51) | J52: =SUM(J6:J51) | ... V52: =SUM(V6:V51) | AA52: =SUM(AA6:AA51)

Sheet Cronograma de Amortização
A1: CRONOGRAMA DE AMORTIZAÇÃO | POR INSTRUMENTO DE DÍVIDA | UMA LINHA = UM INSTRUMENTO
A2: IDENTIFICAÇÃO | C2: INSTRUMENTO | E2: DADOS DO INSTRUMENTO
A3: Empresa | B3: Setor | C3: Tipo de Instrumento (Debênture / Bond / NP / CRA / CCB / Bancário) | D3: Série / Emissão | E3: Data de Emissão | F3: Saldo Devedor (R$ mm) | G3: Moeda | H3: Vencimento Final | I3: Próx. Amortização (data) | J3: Valor Próx. Amort (R$ mm) | K3: Taxa Contratada | L3: Indexador / Benchmark | M3: Observações / Warning
A4: ⚠ Preencher uma linha por instrumento relevante. Azul = Input manual. Fórmulas automáticas em cinza (dias para vencimento, flag de curto prazo).
A5: Energisa | B5: Energia Elétrica
A8: Cemig | B8: Energia Elétrica
A11: CPFL | B11: Energia Elétrica
A14: Desktop | B14: Telecom / ISP
A17: Unifique | B17: Telecom / ISP
A20: Brisanet | B20: Telecom / ISP
A23: Vero | B23: Telecom / ISP
A26: Alloha | B26: Telecom / ISP
A29: Alares | B29: Telecom / ISP
A32: Tecpar / BrTecPar | B32: Telecom / ISP
A35: Algar | B35: Telecom / ISP
A38: TIM | B38: Telecom
... A107: BRF | B107: Alimentos
A110: Ânima | B110: Educação | C110: Debênture | D110: 4ª Emissão — Série 1 | E110: 44923 | F110: 596.6 | G110: BRL | H110: 46734 | I110: 46734 | J110: 596.6 | K110: CDI+1,65% aa | L110: CDI | M110: Bullet. Covenant: DL/EBITDA Ajustado Pf ≤3,0x; EBITDA Pf/Desp.Fin. ≥1,3
A111: Ânima | B111: Educação | C111: Debênture | D111: 4ª Emissão — Série 2 | E111: 44923 | F111: 211.6 | G111: BRL | H111: 47465 | I111: 47100 | K111: IPCA+8,05% aa | L111: IPCA | M111: Amort. anual: dez/2028 e dez/2029. Covenant: igual Série 1
A112: Ânima | B112: Educação | C112: Debênture | D112: 5ª Emissão | E112: 45434 | F112: 211.4 | G112: BRL | H112: 47253 | I112: 46157 | K112: CDI+1,92% aa | L112: CDI | M112: Amort. anual a partir mai/2026. Covenant: DL/EBITDA Ajustado Pf ≤3,0x
A113: Ânima | B113: Educação | C113: Debênture | D113: 6ª Emissão | E113: 45524 | F113: 319.8 | G113: BRL | H113: 47346 | I113: 46250 | K113: CDI+1,92% aa | L113: CDI | M113: Amort. semestral a partir fev/2026. Covenant: DL/EBITDA Ajustado Pf ≤3,0x
A114: Ânima | B114: Educação | C114: Debênture | D114: 7ª Emissão | E114: 45798 | F114: 157.4 | G114: BRL | H114: 47436 | I114: 46887 | K114: CDI+1,60% aa | L114: CDI | M114: 2 parcelas: mai/2028 e nov/2029. Covenant: DL/EBITDA Ajustado Pf ≤3,0x
A115: Ânima | B115: Educação | C115: Debênture | D115: 8ª Emissão | E115: 45945 | F115: 315.3 | G115: BRL | H115: 47406 | I115: 47041 | K115: CDI+1,50% aa | L115: CDI | M115: Amort. a partir out/2028. Covenant: DL/EBITDA Ajustado Pf ≤3,0x
A116: Ânima | B116: Educação | C116: Bancário | D116: Banco ABC 3 | E116: 45565 | F116: 104.4 | G116: BRL | H116: 46657 | I116: 46200 | K116: CDI+1,75% aa | L116: CDI | M116: Amort. trim. desde dez/2025. Covenant: DL/EBITDA Ajustado Pf ≤3,0x
A117: Ânima | B117: Educação | C117: Bancário | D117: BB Capital de Giro 1 | E117: 45105 | F117: 87.2 | G117: BRL | H117: 47386 | I117: 46471 | K117: CDI+1,65% aa | L117: CDI | M117: Amort. semestral. Covenant: DL/EBITDA ajustado <3,5x aa
A118: Ânima | B118: Educação | C118: Bancário | D118: BB Capital de Giro 2 | E118: 45043 | F118: 81 | G118: BRL | H118: 47389 | I118: 46474 | K118: CDI+1,65% aa | L118: CDI | M118: Amort. semestral. Sem covenant explícito
A119: Ânima | B119: Educação | C119: Bancário | D119: BB Capital de Giro 3 | E119: 45111 | F119: 88.3 | G119: BRL | H119: 47386 | I119: 46471 | K119: CDI+1,65% aa | L119: CDI | M119: Amort. semestral. Covenant: DL/EBITDA ajustado <3,5x aa
A120: Ânima | B120: Educação | C120: Empréstimo | D120: IFC (USD) | E120: 44022 | F120: 81.1 | G120: USD | H120: 46827 | K120: SOFR+2,43% aa | L120: SOFR | M120: Moeda original USD; convertido BRL pelo câmbio do balanço. Covenant: Caixa/Div.CP ≥1,20; DL/EBITDA ajustado <3; EBITDA ajustado/Desp.Fin.líquida ≥1,30
A121: Ânima | B121: Educação | C121: Debênture | D121: Inspirali — 2ª Emissão | E121: 45439 | F121: 2110.6 | G121: BRL | H121: 47253 | I121: 46522 | K121: CDI+1,65% aa | L121: CDI | M121: Amort. anual mai/2027→2029. Covenant: DL/EBITDA Ajustado Pf ≤3,5x; EBITDA Pf/Desp.Fin. ≥1,3
A122: Ânima | B122: Educação | C122: Bancário | D122: BB Capital de Giro (Rede) | E122: 44372 | F122: 124.3 | G122: BRL | H122: 47021 | I122: 46290 | K122: CDI+1,65% aa | L122: CDI | M122: Amort. semestral desde mar/2025. Covenant: DL/EBITDA <3,5x
A123: Inspiralli | B123: Educação
A126: Yduqs | B126: Educação | C126: Bancário | D126: CCB - Itaú | F126: 208.9 | G126: BRL | H126: 46173 | I126: 46173 | J126: 208.9 | K126: CDI+1,15% aa | L126: CDI | M126: Prazo médio 0,2 anos (CP). Saldo e data: estimados por prazo médio e pro-rata
A127: Yduqs | B127: Educação | C127: Debênture | D127: 7ª Emissão (Única) | F127: 312.7 | G127: BRL | H127: 46752 | K127: CDI+0,78% aa | L127: CDI | M127: Prazo médio 1,7 anos. Data e saldo: estimados
A128: Yduqs | B128: Educação | C128: Debênture | D128: 8ª Emissão (Única) | F128: 498.7 | G128: BRL | H128: 47664 | K128: CDI+0,85% aa | L128: CDI | M128: Prazo médio 4,2 anos. Data e saldo: estimados
A129: Yduqs | B129: Educação | C129: Debênture | D129: 9ª Emissão — 1ª série | F129: 297.9 | G129: BRL | H129: 47026 | K129: CDI+0,82% aa | L129: CDI | M129: Prazo médio 2,5 anos. Data e saldo: estimados
A130: Yduqs | B130: Educação | C130: Debênture | D130: 9ª Emissão — 2ª série | F130: 333.9 | G130: BRL | H130: 46843 | K130: CDI+0,90% aa | L130: CDI | M130: Prazo médio 2,0 anos. Data e saldo: estimados
A131: Yduqs | B131: Educação | C131: Debênture | D131: 9ª Emissão — 3ª série | F131: 112 | G131: BRL | H131: 47573 | K131: CDI+0,98% aa | L131: CDI | M131: Prazo médio 4,0 anos. Data e saldo: estimados
A132: Yduqs | B132: Educação | C132: Debênture | D132: 10ª Emissão (Única) | F132: 1173.1 | G132: BRL | H132: 47026 | K132: CDI+1,25% aa | L132: CDI | M132: Prazo médio 2,5 anos. Maior instrumento (31% da dívida). Data e saldo: estimados
A133: Yduqs | B133: Educação | C133: Debênture | D133: 11ª Emissão (Única) | F133: 313.1 | G133: BRL | H133: 47999 | K133: CDI+1,05% aa | L133: CDI | M133: Prazo médio 5,2 anos. Data e saldo: estimados
A134: Yduqs | B134: Educação | C134: Debênture | D134: 12ª Emissão (Única) | F134: 516.4 | G134: BRL | H134: 47514 | K134: CDI+0,70% aa | L134: CDI | M134: Prazo médio 3,7 anos. Data e saldo: estimados
...

Sheet Wall of Maturities
A1: WALL OF MATURITIES | VENCIMENTOS CONSOLIDADOS POR ANO (R$ mm)
A2: Empresa | B2: Setor | C2: 2025 | D2: 2026 | E2: 2027 | F2: 2028 | G2: 2029 | H2: 2030 | I2: 2031 | J2: 2032 | K2: 2033 | L2: 2034 | M2: 2035 | N2: 2036+ | O2: Total
A3: Energisa | B3: Energia Elétrica | O3: =SUM(C3:N3)
A4: Cemig | B4: Energia Elétrica | O4: =SUM(C4:N4)
A5: CPFL | B5: Energia Elétrica | O5: =SUM(C5:N5)
A6: Desktop | B6: Telecom / ISP | O6: =SUM(C6:N6)
A7: Unifique | B7: Telecom / ISP | O7: =SUM(C7:N7)
A8: Brisanet | B8: Telecom / ISP | O8: =SUM(C8:N8)
A9: Vero | B9: Telecom / ISP | O9: =SUM(C9:N9)
A10: Alloha | B10: Telecom / ISP | O10: =SUM(C10:N10)
A11: Alares | B11: Telecom / ISP | O11: =SUM(C11:N11)
A12: Tecpar / BrTecPar | B12: Telecom / ISP | O12: =SUM(C12:N12)
A13: Algar | B13: Telecom / ISP | O13: =SUM(C13:N13)
A14: TIM | B14: Telecom | O14: =SUM(C14:N14)
... A37: BRF | B37: Alimentos | O37: =SUM(C37:N37)
A38: Ânima | B38: Educação | D38: 474.8 | E38: 1625 | F38: 1224.8 | G38: 1174.4 | O38: =SUM(C38:N38)
A39: Inspiralli | B39: Educação | O39: =SUM(C39:N39)
A40: Yduqs | B40: Educação | D40: 200 | E40: 457 | F40: 988 | G40: 1103 | H40: 703 | I40: 150 | O40: =SUM(C40:N40)
A41: Afya | B41: Educação Médica | D41: 132.1 | E41: 132 | F41: 630 | G41: 134 | H41: 996 | O41: =SUM(C41:N41)
A42: Cruzeiro do Sul | B42: Educação | O42: =SUM(C42:N42)
A43: Cogna | B43: Educação | O43: =SUM(C43:N43)
A44: Vitru | B44: Educação | O44: =SUM(C44:N44)
A45: Ser Educacional | B45: Educação | O45: =SUM(C45:N45)
A46: Salta Educação | B46: Educação | O46: =SUM(C46:N46)
A47: Inspira | B47: Educação | O47: =SUM(C47:N47)
A48: Smartfit | B48: Fitness / Saúde | O48: =SUM(C48:N48)
A49: TOTAL GERAL | C49: =SUM(C3:C48) | D49: =SUM(D3:D48) | E49: =SUM(E3:E48) | F49: =SUM(F3:F48) | G49: =SUM(G3:G48) | H49: =SUM(H3:H48) | I49: =SUM(I3:I48) | J49: =SUM(J3:J48) | ... O49: =SUM(O3:O48)
A51: ℹ Preencher com os saldos devedores por ano de vencimento extraídos da aba 'Cronograma de Amortização'. Considerar apenas amortizações de principal.

Sheet Covenants & Capex
A1: COVENANTS FINANCEIROS | GUIDANCE DE CAPEX | M&A RECENTE
A2: Empresa | B2: Setor | C2: Instrumento / Debenturista | D2: Covenant: DL/ EBITDA — Limite | E2: Covenant: Outro Indicador | F2: Headroom Atual | G2: Guidance Capex 12 meses (R$ mm) | H2: Guidance Capex 24 meses (R$ mm) | I2: M&A Anunciado (Alvo / Valor) | J2: Impacto Alavancagem | K2: Observações
A3: Energisa | B3: Energia Elétrica
A4: Cemig | B4: Energia Elétrica
A5: CPFL | B5: Energia Elétrica
A6: Desktop | B6: Telecom / ISP
A7: Unifique | B7: Telecom / ISP
A8: Brisanet | B8: Telecom / ISP
A9: Vero | B9: Telecom / ISP
A10: Alloha | B10: Telecom / ISP
A11: Alares | B11: Telecom / ISP
A12: Tecpar / BrTecPar | B12: Telecom / ISP
A13: Algar | B13: Telecom / ISP
A14: TIM | B14: Telecom
... A37: BRF | B37: Alimentos
A38: Ânima | B38: Educação | C38: Debs 4ª-8ª (Ânima); Debs 2ª (Inspirali); BB Capital de Giro; IFC | D38: ≤ 3,0x (Debs Ânima); ≤ 3,5x (Inspirali, BB-Rede) | E38: EBITDA Ajustado Pf / Desp.Fin. ≥ 1,3; IFC: Caixa/Div.CP ≥ 1,20 | F38: DL/EBITDA ex-IFRS16 LTM = 2,39x vs limite 3,0x → headroom 0,61x | I38: FASEH 94,42% (R$45,3mm) — concluído fev/2026 | J38: Marginal — deal pequeno e já liquidado | K38: Sem descumprimento de covenants em 31/03/2026 (Nota 12 DF 1T26)
A39: Inspiralli | B39: Educação
A40: Yduqs | B40: Educação | C40: Debêntures VII-XII; CCB Itaú | D40: Não disponível sem Notas Explicativas — DL/EBITDA ajustado LTM = 1,53x | E40: Não disponível sem Notas Explicativas | F40: DL/EBITDA Ajustado (ex-IFRS16) LTM = 1,53x — leverage muito baixa | I40: Unifametro (medicina, IDOMED) — adquirida 1T26; pagamento parcial R$75,5mm | J40: Marginal — leverage aumentou de 1,59x para 1,53x (redução no período) | K40: FCA guidance 2026: R$520-620mm. Custo médio dívida: CDI+0,99%. Sem info covenant nos documentos disponíveis.
A41: Afya | B41: Educação Médica | C41: Notas Comerciais 1ª e 2ª Série; IFC; Contas a pagar a vendedores | D41: Net Debt / Adjusted EBITDA ≤ 3,0x (excl. IFRS16, Notas Comerciais) | E41: Conforme Commercial Notes (press release 4T25, pg.2) | F41: DL/EBITDA Ajustado mid-guidance 2026 = 0,7x vs limite 3,0x → headroom 2,3x | G41: 360 | I41: FUNIC (60 vagas medicina, dez/2025, licença R$99,6mm); 63 vagas MEC Abaetetuba fev/2026 | J41: Impacto marginal — alavancagem reduzindo de 0,8x para 0,7x | K41: Rating: AAA.br (Moody's, mai/2026). DL/EBITDA ex-IFRS16 1Q26 = 0,7x. FY2025 compliant.
A42: Cruzeiro do Sul | B42: Educação
A43: Cogna | B43: Educação
A44: Vitru | B44: Educação
A45: Ser Educacional | B45: Educação
A46: Salta Educação | B46: Educação
A47: Inspira | B47: Educação
A48: Smartfit | B48: Fitness / Saúde

Sheet Fontes — RI
A1: FONTES | SITES DE RELAÇÕES COM INVESTIDORES
A2: Links para os portais de RI das empresas em cobertura. Verificar release do último trimestre e/ou apresentação de resultados para preenchimento das abas.
A3: Empresa | B3: Ticker | C3: Setor | D3: Link Portal RI | E3: Última Atualização / Nota
A4: ▌ ENERGIA ELÉTRICA
A5: Energisa | B5: ENGI11 | C5: Energia Elétrica | D5: https://www.energisa.com.br/Paginas/Informacoes/Investidores.aspx
A6: Cemig | B6: CMIG4 | C6: Energia Elétrica | D6: https://ri.cemig.com.br/
A7: CPFL | B7: CPFE3 | C7: Energia Elétrica | D7: https://ri.cpfl.com.br/
A8: ▌ TELECOM / ISP
A9: Desktop | B9: DESK3 | C9: Telecom / ISP | D9: https://ri.desktop.com.br/
A10: Unifique | B10: FIQE3 | C10: Telecom / ISP | D10: https://ri.unifique.com.br/
A11: Brisanet | B11: BRIT3 | C11: Telecom / ISP | D11: https://ri.brisanet.com.br/
A12: Vero | B12: N/A | C12: Telecom / ISP | D12: https://www.vero.net.br/ri
A13: Alloha | B13: N/A | C13: Telecom / ISP | D13: https://www.allohari.com/
A14: Alares | B14: N/A | C14: Telecom / ISP | D14: https://ri.alaresinternet.com.br/
A15: Tecpar / BrTecPar | B15: N/A | C15: Telecom / ISP | D15: https://ri.brasiltecpar.com.br/
A16: Algar | B16: ALGT3 | C16: Telecom / ISP | D16: https://ri.algar.com.br/
A17: ▌ TELECOM
A18: TIM | B18: TIMS3 | C18: Telecom | D18: https://ri.tim.com.br/
A19: ▌ LOCAÇÃO / TRANSPORTE
A20: Vamos | B20: VAMO3 | C20: Locação / Transporte | D20: https://ri.vamos.com.br/
A21: Movida | B21: MOVI3 | C21: Locação / Transporte | D21: https://ri.movida.com.br/
A22: ▌ LOGÍSTICA
A23: JSL | B23: JSLG3 | C23: Logística | D23: https://ri.jsl.com.br/
A24: ▌ INFRAESTRUTURA / RODOV.
A25: Ecorodovias | B25: ECOR3 | C25: Infraestrutura / Rodov. | D25: https://ri.ecorodovias.com.br/
A26: ▌ PORTO / LOGÍSTICA
A27: Santos Brasil | B27: STBP3 | C27: Porto / Logística | D27: https://ri.santosbrasil.com.br/
A28: ▌ SANEAMENTO
A29: Copasa | B29: CSMG3 | C29: Saneamento | D29: https://ri.copasa.com.br/
A30: Sanepar | B30: SAPR11 | C30: Saneamento | D30: https://www.sanepar.com.br/ri
A31: Saneago | B31: SAAG4 | C31: Saneamento | D31: https://ri.saneago.com.br/
A32: ▌ LOGÍSTICA / TRANSPORTE
A33: Vix | B33: VIIA3 | C33: Logística / Transporte | D33: https://ri.vix.com.br/
A34: ▌ LOCAÇÃO
A35: Armac | B35: ARML3 | C35: Locação | D35: https://ri.armac.com.br/
A36: Unidas | B36: LCAM3 | C36: Locação | D36: https://ri.unidas.com.br/
A37: ▌ LOCAÇÃO / INDÚSTRIA
A38: Mills | B38: MILS3 | C38: Locação / Indústria | D38: https://ri.mills.com.br/
A39: ▌ SERVIÇOS INDUSTRIAIS
A40: Priner | B40: PRNR3 | C40: Serviços Industriais | D40: https://ri.priner.com.br/
...

Sheet Notas Metodológicas
A1: NOTAS METODOLÓGICAS | DEFINIÇÕES E CONVENÇÕES
A2: Campo / Métrica | B2: Definição e Metodologia
A3: PERÍODO BASE | B3: Último quarter com LTM (Last Twelve Months) divulgado. Ajustar label na aba 'Painel de Crédito' conforme publicação de resultados.
A4: DÍVIDA BRUTA | B4: Total de dívidas financeiras onerosas: debêntures, bonds, CRAs, NPs, CCBs, empréstimos bancários e arrendamentos (IFRS 16 a critério do analista — indicar se incluído).
A5: CAIXA | B5: Caixa e equivalentes + aplicações financeiras de curto prazo. Excluir restritos.
A6: DÍVIDA LÍQUIDA | B6: Dívida Bruta – Caixa. Fórmula automática na planilha. Se negativo, indica posição de caixa líquido.
A7: EBITDA LTM | B7: EBITDA ajustado LTM conforme reportado pela companhia (preferir EBITDA recorrente/ajustado divulgado no release). Se não divulgado, calcular: EBIT + D&A.
A8: DL / EBITDA | B8: Alavancagem financeira. Calculado automaticamente. Referência: >4,0x = elevado; 2,0-4,0x = moderado; <2,0x = baixo (parâmetros setoriais variam).
A9: EBITDA / DESP. FIN. | B9: Índice de cobertura de juros (ICJ). Input manual. Referência: <2,0x = zona de atenção; >3,0x = confortável.
A10: CUSTO MÉDIO | B10: Custo médio ponderado da dívida (% a.a.), conforme disclosure da companhia ou calculado via juros pagos / saldo médio. Indicar se CDI+spread ou % CDI.
A11: DURATION MÉDIA | B11: Prazo médio ponderado da dívida em anos, considerando fluxos de principal e juros, ou conforme disclosure da empresa.
A12: % CURTO PRAZO | B12: Parcela da dívida bruta vencendo em até 12 meses / dívida bruta total.
A13: DÍVIDA CP | B13: Saldo da dívida com vencimento em até 12 meses (circulante). Fonte: notas explicativas.
... A22: ATUALIZAÇÃO | B22: Recomendado atualizar a cada ciclo de resultados (trimestral). Registrar data de atualização na col. 'Última Atualização' da aba Fontes—RI.

Sheet Disclaimers
A1: Empresa | B1: Campo Afetado | C1: Situação | D1: Detalhamento | E1: Fonte (doc + página) | F1: Data do Documento
A2: Ânima | B2: Período / LTM | C2: Calculado | D2: LTM = FY2025 (4T25 release) − 1T25 + 1T26 (ITR 1T26) | E2: Anima_Release_4T25_PT.pdf pg.1; Anima_Release_1T26.pdf pg.1 | F2: 12/03/2026; 06/05/2026
A3: Ânima | B3: Receita Líquida LTM | C3: Calculado | D3: R$4.109,4mm — figura explícita do release 1T26 (PMR pág.10). Cálculo via fórmula: 4.023,7−1.040,1+1.120,4=4.104,0mm (dif. de R$5,4mm por arredondamento nos trimestrais). | E3: Anima_Release_1T26.pdf pg.10 | F3: 06/05/2026
A4: Ânima | B4: EBIT LTM | C4: Calculado | D4: 1.002,0−304,6+325,6=R$1.023,0mm. EBIT = Resultado antes do resultado financeiro (IFRS). Inclui equivalência patrimonial. | E4: Anima_Release_4T25_PT.pdf pg.20; Anima_DF_1T26.pdf pg.5 | F4: 12/03/2026; 06/05/2026
A5: Ânima | B5: D&A LTM | C5: Calculado | D5: 427,4−109,4+102,8=R$420,8mm. D&A inclui amortização de ativo de direito de uso (IFRS16). Hierarquia (3): calculado. | E5: Anima_Release_4T25_PT.pdf pg.15; Anima_Release_1T26.pdf pg.9 | F5: 12/03/2026; 06/05/2026
A6: Ânima | B6: EBITDA LTM (col V) | C6: Calculado | D6: EBITDA (fórmula) = EBIT+D&A = R$1.443,8mm. Release: EBITDA Ajustado ex-IFRS16 LTM = R$1.222,2mm (excl. IFRS16 e ajustes). Hierarquia usada: (3) EBIT+D&A. | E6: Anima_Release_1T26.pdf pg.10 | F6: 06/05/2026
A7: Ânima | B7: Desp. Financ. Bruta LTM | C7: Calculado | D7: Excluída despesa IFRS16 de arrendamento: (1.001,6−142,9)−(225,0−36,1)+(259,4−41,9)=R$887,3mm. Linha 'Desp. comissões/juros empréstimos' pode incluir efeito cambial do swap IFC (não separável). | E7: Anima_Release_4T25_PT.pdf pg.14; Anima_DF_1T26.pdf pg.8 | F7: 12/03/2026; 06/05/2026
A8: Ânima | B8: Rec. Financeira LTM | C8: Calculado | D8: 252,5−53,8+74,0=R$272,7mm. | E8: Anima_Release_4T25_PT.pdf pg.14; Anima_Release_1T26.pdf pg.8 | F8: 12/03/2026; 06/05/2026
A9: Ânima | B9: Capex LTM | C9: Calculado | D9: 217,3−51,0+54,5=R$220,8mm. Capex total (imobilizado+intangível), excluído M&A (FASEH R$45,3mm e outras aquisições). | E9: Anima_Release_4T25_PT.pdf pg.18; Anima_Release_1T26.pdf pg.12 | F9: 12/03/2026; 06/05/2026
A10: Ânima | B10: Caixa e Aplicações CP | C10: Ajustado | D10: Aplicações LP (R$25,7mm) excluídas do caixa CP. R$31,8mm das aplicações estão em garantia (parcialmente restritas) — mantidas por representar <2% do total. | E10: Anima_DF_1T26.pdf Nota 5 pg.13 | F10: 06/05/2026
A11: Ânima | B11: Emp. & Fin. CP/LP | C11: Ajustado | D11: Excluídos derivativos CP (R$20,1mm) e LP (R$21,8mm) conforme R10. Inclui debêntures e empréstimos bancários consolidados (Nota 12). | E11: Anima_DF_1T26.pdf Nota 12 pg.26; Balanço pg.4 | F11: 06/05/2026
A12: Ânima | B12: Valor Próx. Amortização | C12: Não disponível | D12: Valores exatos por parcela não detalhados no Nota 12 do ITR 1T26 para instrumentos com amortização parcial. Deixados em branco. | E12: Anima_DF_1T26.pdf Nota 12 pg.26-27 | F12: 06/05/2026
... A34: Afya | B34: Cronograma — IFC | C34: Estimado | D34: Data de emissão IFC e datas de amortização: estimadas. Moeda original USD (convertida BRL pelo câmbio do balanço). SOFR+spread: custo total = 15,8% aa em 1Q26 (CDI+108%). | E34: Afya_Release_1T26.pdf Table 10 | F34: 07/05/2026

Sheet Oportunidades de Deal
A1: Empresa | B1: Setor | C1: Tipo de Oportunidade | D1: Instrumento Sugerido | E1: Tamanho Estimado | F1: Racional | G1: Estrutura Sugerida | H1: Prioridade | I1: Timing
A2: Ânima | B2: Educação | C2: Refinanciamento Preventivo | D2: Debêntures CDI+ 5-7 anos | E2: R$ 1.600–1.800mm | F2: Wall de vencimentos em 2027 representa R$1.625mm (36% da dívida total): Debs 4ª Série 1 (R$597mm bullet dez/2027) + Banco ABC (R$104mm set/2027) + parcelas BB. DL/EBITDA de 2,39x oferece headroom confortável para nova emissão a custo competitivo. | G2: Debêntures CDI+ em 5-7 anos com amortização anual a partir do ano 3. Possível estrutura IPCA+ para tranche de prazo mais longo (7+ anos) se condições de mercado permitirem. | H2: Alta | I2: 2H26 — emissão preferencial antes de set/2026 para evitar sazonalidade negativa do 2T
A3: Ânima | B3: Educação | C3: Emissão Incremental / M&A | D3: Debêntures Inspirali CDI+ ou IPCA+ | E3: R$ 500–800mm | F3: Inspirali (medicina) tem perfil de crédito superior: margem operacional de 52,8% e crescimento de receita de 9,8% em 2025. Emissão segregada captura prêmio de crédito mais favorável vs. holding. Potencial de elegibilidade como infraestrutura educacional médica (Lei 12.431) para cursos de medicina. | G3: Debêntures Inspirali com covenant específico ≤3,5x DL/EBITDA; possível estruturação como IPCA+ via Lei 12.431 caso aprovação regulatória. Garantia da holding Ânima como credit support. | H3: Média | I3: 1H27 — após estabilização regulatória do Novo Marco Regulatório do EAD
A4: Yduqs | B4: Educação | C4: Pré-Refinanciamento | D4: Debêntures CDI+ 5-7 anos | E4: R$ 988–1.200mm | F4: Wall concentrada em 2028 (R$988mm de Debs IX séries 1 e 2 + parcela Debs X): R$1.500mm+ vencendo em 2028. Aproveitamento de alavancagem muito baixa (1,53x) e FCO robusto (R$457,9mm no 1T26) para alongar perfil a custo favorável. Guidance FCA de R$520-620mm em 2026 sinaliza forte geração de caixa estrutural. | G4: Debêntures CDI+ em 5-7 anos com amortização anual a partir do ano 3. Possível estrutura em duas tranches: Série 1 (CDI+) para varejo e Série 2 (IPCA+) para investidores institucionais de prazo longo. | H4: Alta | I4: 2H26 — antes de eventual estresse de mercado e aproveitando janela pós-ciclo de alta Selic
A5: Yduqs | B5: Educação | C5: Crescimento Premium | D5: Debêntures IPCA+ (Lei 12.431) | E5: R$ 500–700mm | F5: IDOMED (medicina) crescendo 10% em ROL e 8% em EBITDA. Ibmec crescendo 23% em ROL e 34% em EBITDA. Expansão em campi médicos/negócios de alta qualidade pode ser financiada por debêntures de infraestrutura se classificada como infraestrutura educacional (medicina). Baixa alavancagem permite incremento de ~R$700mm sem violar covenants típicos de 3,0x. | G5: Debêntures Lei 12.431 (IPCA+ isento IR para PF) se elegíveis; ou CDI+ em SFN com garantia fiduciária das marcas/receitas Ibmec/IDOMED. Avaliação de elegibilidade regulatória necessária. | H5: Média | I5: 2026-2027 — pós aprovação de novos campi e/ou M&A adicional
A6: Afya | B6: Educação | C6: Refinanciamento IFC / Diversificação | D6: Debêntures CDI+ ou IPCA+ 5-7 anos | E6: R$ 500–700mm | F6: IFC (R$530mm) com amortização trimestral e custo 108% do CDI (~15,8% aa) é o instrumento mais caro da estrutura. Refinanciamento via debêntures locais reduziria spread e alongaria perfil. DL/EBITDA de 0,7x (headroom excepcional vs covenant 3,0x) permite emissão incremental se necessário. | G6: Debêntures CDI+ em 5-6 anos com amortização anual a partir do ano 3 (similar às Notas Comerciais existentes). Possível estrutura IPCA+ se Afya qualificar como infraestrutura educacional médica (3.768 vagas de medicina = argumento para Lei 12.431). | H6: Média | I6: 2026-2027 — quando IFC amortizar parcialmente e janela de mercado permitir
A7: Afya | B7: Educação | C7: Expansão M&A | D7: Debêntures CDI+ Incrementais | E7: R$ 800–1.200mm | F7: Afya executa consistente ciclo de M&A (FUNIC 2025, UNIDOM 2024, FIP Guanambi 2024). Com FCF de R$1.056mm em 2025 e guidance 2026 de R$1.700-1.800mm EBITDA, há espaço para leverage adicional de até 2x (DL de ~R$3.400mm) vs atual R$1.151mm. Nova captação financiaria aquisições de vagas médicas a prêmio regulatório. | G7: Debêntures incrementais CDI+ para aquisição de escolas de medicina com vagas MEC (escassas e com deságio natural para compradores). Estrutura de holding (Afya Brazil) com garantias das subsidiárias operacionais. | H7: Alta | I7: 2H26-1H27 — após conclusão do ciclo de integração FUNIC e aprovação de novas vagas MEC
